<sdf version='1.7'>
  <world name='default'>
    <plugin name='ros_link_attacher_plugin' filename='libgazebo_ros_link_attacher.so'/>
    <light name='sun' type='directional'>
      <cast_shadows>1</cast_shadows>
      <pose>0 0 10 0 -0 0</pose>
      <diffuse>0.8 0.8 0.8 1</diffuse>
      <specular>0.2 0.2 0.2 1</specular>
      <attenuation>
        <range>1000</range>
        <constant>0.9</constant>
        <linear>0.01</linear>
        <quadratic>0.001</quadratic>
      </attenuation>
      <direction>-0.5 0.1 -0.9</direction>
      <spot>
        <inner_angle>0</inner_angle>
        <outer_angle>0</outer_angle>
        <falloff>0</falloff>
      </spot>
    </light>
    <model name='ground_plane'>
      <static>1</static>
      <link name='link'>
        <collision name='collision'>
          <geometry>
            <plane>
              <normal>0 0 1</normal>
              <size>100 100</size>
            </plane>
          </geometry>
          <surface>
            <friction>
              <ode>
                <mu>100</mu>
                <mu2>50</mu2>
              </ode>
              <torsional>
                <ode/>
              </torsional>
            </friction>
            <contact>
              <ode/>
            </contact>
            <bounce/>
          </surface>
          <max_contacts>10</max_contacts>
        </collision>
        <visual name='visual'>
          <cast_shadows>0</cast_shadows>
          <geometry>
            <plane>
              <normal>0 0 1</normal>
              <size>100 100</size>
            </plane>
          </geometry>
          <material>
            <script>
              <uri>file://media/materials/scripts/gazebo.material</uri>
              <name>Gazebo/Grey</name>
            </script>
          </material>
        </visual>
        <self_collide>0</self_collide>
        <enable_wind>0</enable_wind>
        <kinematic>0</kinematic>
      </link>
    </model>
    <gravity>0 0 -9.8</gravity>
    <magnetic_field>6e-06 2.3e-05 -4.2e-05</magnetic_field>
    <atmosphere type='adiabatic'/>
    <physics type='ode'>
      <max_step_size>0.001</max_step_size>
      <real_time_factor>1</real_time_factor>
      <real_time_update_rate>1000</real_time_update_rate>
    </physics>
    <scene>
      <ambient>0.4 0.4 0.4 1</ambient>
      <background>0.7 0.7 0.7 1</background>
      <shadows>1</shadows>
    </scene>
    <wind/>
    <spherical_coordinates>
      <surface_model>EARTH_WGS84</surface_model>
      <latitude_deg>0</latitude_deg>
      <longitude_deg>0</longitude_deg>
      <elevation>0</elevation>
      <heading_deg>0</heading_deg>
    </spherical_coordinates>
    <model name='wx250s'>
      <joint name='fixed' type='fixed'>
        <pose relative_to='__model__'>0 0 1.015 0 -0 0</pose>
        <parent>world</parent>
        <child>wx250s/base_link</child>
      </joint>
      <link name='wx250s/base_link'>
        <pose relative_to='fixed'>0 0 0 0 -0 0</pose>
        <inertial>
          <pose>-0.038045 0.000614 0.019335 0 -0 1.5708</pose>
          <mass>0.538736</mass>
          <inertia>
            <ixx>0.002115</ixx>
            <ixy>-1.635e-05</ixy>
            <ixz>6.998e-07</ixz>
            <iyy>0.0006921</iyy>
            <iyz>4.642e-05</iyz>
            <izz>0.002524</izz>
          </inertia>
        </inertial>
        <collision name='wx250s/base_link_collision'>
          <pose>0 0 0 0 -0 1.5708</pose>
          <geometry>
            <mesh>
              <scale>0.001 0.001 0.001</scale>
              <uri>/home/interbotix_ws/src/interbotix_ros_manipulators/interbotix_ros_xsarms/interbotix_xsarm_descriptions/meshes/wx250s_meshes/wx250s_1_base.stl</uri>
            </mesh>
          </geometry>
          <surface>
            <contact>
              <ode/>
            </contact>
            <friction>
              <ode/>
              <torsional>
                <ode/>
              </torsional>
            </friction>
            <bounce/>
          </surface>
          <max_contacts>10</max_contacts>
        </collision>
        <visual name='wx250s/base_link_visual'>
          <pose>0 0 0 0 -0 1.5708</pose>
          <geometry>
            <mesh>
              <scale>0.001 0.001 0.001</scale>
              <uri>/home/interbotix_ws/src/interbotix_ros_manipulators/interbotix_ros_xsarms/interbotix_xsarm_descriptions/meshes/wx250s_meshes/wx250s_1_base.stl</uri>
            </mesh>
          </geometry>
          <material>
            <script>
              <name>Custom/Interbotix</name>
              <uri>file://media/materials/scripts/gazebo.material</uri>
            </script>
          </material>
        </visual>
        <velocity_decay>
          <linear>0.1</linear>
          <angular>0.1</angular>
        </velocity_decay>
        <self_collide>0</self_collide>
        <enable_wind>0</enable_wind>
        <kinematic>0</kinematic>
      </link>
      <joint name='waist' type='revolute'>
        <pose relative_to='wx250s/base_link'>0 0 0.072 0 -0 0</pose>
        <parent>wx250s/base_link</parent>
        <child>wx250s/shoulder_link</child>
        <axis>
          <xyz>0 0 1</xyz>
          <limit>
            <lower>-3.14158</lower>
            <upper>3.14158</upper>
            <effort>10</effort>
            <velocity>3.14159</velocity>
          </limit>
          <dynamics>
            <damping>0</damping>
            <friction>0.1</friction>
            <spring_reference>0</spring_reference>
            <spring_stiffness>0</spring_stiffness>
          </dynamics>
        </axis>
      </joint>
      <link name='wx250s/shoulder_link'>
        <pose relative_to='waist'>0 0 0 0 -0 0</pose>
        <inertial>
          <pose>2.2e-05 4.1e-05 0.006629 0 -0 1.5708</pose>
          <mass>0.480879</mass>
          <inertia>
            <ixx>0.000379</ixx>
            <ixy>2.2e-09</ixy>
            <ixz>-3.561e-07</ixz>
            <iyy>0.0005557</iyy>
            <iyz>1.2245e-06</iyz>
            <izz>0.0005889</izz>
          </inertia>
        </inertial>
        <collision name='wx250s/shoulder_link_collision'>
          <pose>0 0 -0.003 0 -0 1.5708</pose>
          <geometry>
            <mesh>
              <scale>0.001 0.001 0.001</scale>
              <uri>/home/interbotix_ws/src/interbotix_ros_manipulators/interbotix_ros_xsarms/interbotix_xsarm_descriptions/meshes/wx250s_meshes/wx250s_2_shoulder.stl</uri>
            </mesh>
          </geometry>
          <surface>
            <contact>
              <ode/>
            </contact>
            <friction>
              <ode/>
              <torsional>
                <ode/>
              </torsional>
            </friction>
            <bounce/>
          </surface>
          <max_contacts>10</max_contacts>
        </collision>
        <visual name='wx250s/shoulder_link_visual'>
          <pose>0 0 -0.003 0 -0 1.5708</pose>
          <geometry>
            <mesh>
              <scale>0.001 0.001 0.001</scale>
              <uri>/home/interbotix_ws/src/interbotix_ros_manipulators/interbotix_ros_xsarms/interbotix_xsarm_descriptions/meshes/wx250s_meshes/wx250s_2_shoulder.stl</uri>
            </mesh>
          </geometry>
          <material>
            <script>
              <name>Custom/Interbotix</name>
              <uri>file://media/materials/scripts/gazebo.material</uri>
            </script>
          </material>
        </visual>
        <velocity_decay>
          <linear>0.1</linear>
          <angular>0.1</angular>
        </velocity_decay>
        <self_collide>0</self_collide>
        <enable_wind>0</enable_wind>
        <kinematic>0</kinematic>
      </link>
      <joint name='shoulder' type='revolute'>
        <pose relative_to='wx250s/shoulder_link'>0 0 0.03865 0 -0 0</pose>
        <parent>wx250s/shoulder_link</parent>
        <child>wx250s/upper_arm_link</child>
        <axis>
          <xyz>0 1 0</xyz>
          <limit>
            <lower>-1.88496</lower>
            <upper>1.98968</upper>
            <effort>20</effort>
            <velocity>3.14159</velocity>
          </limit>
          <dynamics>
            <damping>0</damping>
            <friction>0.1</friction>
            <spring_reference>0</spring_reference>
            <spring_stiffness>0</spring_stiffness>
          </dynamics>
        </axis>
      </joint>
      <link name='wx250s/upper_arm_link'>
        <pose relative_to='shoulder'>0 0 0 0 -0 0</pose>
        <inertial>
          <pose>0.017161 0 0.191323 0 -0 1.5708</pose>
          <mass>0.430811</mass>
          <inertia>
            <ixx>0.003463</ixx>
            <ixy>-1e-10</ixy>
            <ixz>-2e-10</ixz>
            <iyy>0.003587</iyy>
            <iyz>0.0004272</iyz>
            <izz>0.0004566</izz>
          </inertia>
        </inertial>
        <collision name='wx250s/upper_arm_link_collision'>
          <pose>0 0 0 0 -0 1.5708</pose>
          <geometry>
            <mesh>
              <scale>0.001 0.001 0.001</scale>
              <uri>/home/interbotix_ws/src/interbotix_ros_manipulators/interbotix_ros_xsarms/interbotix_xsarm_descriptions/meshes/wx250s_meshes/wx250s_3_upper_arm.stl</uri>
            </mesh>
          </geometry>
          <surface>
            <contact>
              <ode/>
            </contact>
            <friction>
              <ode/>
              <torsional>
                <ode/>
              </torsional>
            </friction>
            <bounce/>
          </surface>
          <max_contacts>10</max_contacts>
        </collision>
        <visual name='wx250s/upper_arm_link_visual'>
          <pose>0 0 0 0 -0 1.5708</pose>
          <geometry>
            <mesh>
              <scale>0.001 0.001 0.001</scale>
              <uri>/home/interbotix_ws/src/interbotix_ros_manipulators/interbotix_ros_xsarms/interbotix_xsarm_descriptions/meshes/wx250s_meshes/wx250s_3_upper_arm.stl</uri>
            </mesh>
          </geometry>
          <material>
            <script>
              <name>Custom/Interbotix</name>
              <uri>file://media/materials/scripts/gazebo.material</uri>
            </script>
          </material>
        </visual>
        <velocity_decay>
          <linear>0.1</linear>
          <angular>0.1</angular>
        </velocity_decay>
        <self_collide>0</self_collide>
        <enable_wind>0</enable_wind>
        <kinematic>0</kinematic>
      </link>
      <joint name='elbow' type='revolute'>
        <pose relative_to='wx250s/upper_arm_link'>0.04975 0 0.25 0 -0 0</pose>
        <parent>wx250s/upper_arm_link</parent>
        <child>wx250s/upper_forearm_link</child>
        <axis>
          <xyz>0 1 0</xyz>
          <limit>
            <lower>-2.14675</lower>
            <upper>1.6057</upper>
            <effort>15</effort>
            <velocity>3.14159</velocity>
          </limit>
          <dynamics>
            <damping>0</damping>
            <friction>0.1</friction>
            <spring_reference>0</spring_reference>
            <spring_stiffness>0</spring_stiffness>
          </dynamics>
        </axis>
      </joint>
      <link name='wx250s/upper_forearm_link'>
        <pose relative_to='elbow'>0 0 0 0 -0 0</pose>
        <inertial>
          <pose>0.107963 0.000116 0 0 -0 0</pose>
          <mass>0.234589</mass>
          <inertia>
            <ixx>3.971e-05</ixx>
            <ixy>2.3528e-06</ixy>
            <ixz>0</ixz>
            <iyy>0.0008878</iyy>
            <iyz>0</iyz>
            <izz>0.000888</izz>
          </inertia>
        </inertial>
        <collision name='wx250s/upper_forearm_link_collision'>
          <pose>0 0 0 0 -0 0</pose>
          <geometry>
            <mesh>
              <scale>0.001 0.001 0.001</scale>
              <uri>/home/interbotix_ws/src/interbotix_ros_manipulators/interbotix_ros_xsarms/interbotix_xsarm_descriptions/meshes/wx250s_meshes/wx250s_4_upper_forearm.stl</uri>
            </mesh>
          </geometry>
          <surface>
            <contact>
              <ode/>
            </contact>
            <friction>
              <ode/>
              <torsional>
                <ode/>
              </torsional>
            </friction>
            <bounce/>
          </surface>
          <max_contacts>10</max_contacts>
        </collision>
        <visual name='wx250s/upper_forearm_link_visual'>
          <pose>0 0 0 0 -0 0</pose>
          <geometry>
            <mesh>
              <scale>0.001 0.001 0.001</scale>
              <uri>/home/interbotix_ws/src/interbotix_ros_manipulators/interbotix_ros_xsarms/interbotix_xsarm_descriptions/meshes/wx250s_meshes/wx250s_4_upper_forearm.stl</uri>
            </mesh>
          </geometry>
          <material>
            <script>
              <name>Custom/Interbotix</name>
              <uri>file://media/materials/scripts/gazebo.material</uri>
            </script>
          </material>
        </visual>
        <velocity_decay>
          <linear>0.1</linear>
          <angular>0.1</angular>
        </velocity_decay>
        <self_collide>0</self_collide>
        <enable_wind>0</enable_wind>
        <kinematic>0</kinematic>
      </link>
      <joint name='forearm_roll' type='revolute'>
        <pose relative_to='wx250s/upper_forearm_link'>0.175 0 0 0 -0 0</pose>
        <parent>wx250s/upper_forearm_link</parent>
        <child>wx250s/lower_forearm_link</child>
        <axis>
          <xyz>1 0 0</xyz>
          <limit>
            <lower>-3.14158</lower>
            <upper>3.14158</upper>
            <effort>2</effort>
            <velocity>3.14159</velocity>
          </limit>
          <dynamics>
            <damping>0</damping>
            <friction>0.1</friction>
            <spring_reference>0</spring_reference>
            <spring_stiffness>0</spring_stiffness>
          </dynamics>
        </axis>
      </joint>
      <link name='wx250s/lower_forearm_link'>
        <pose relative_to='forearm_roll'>0 0 0 0 -0 0</pose>
        <inertial>
          <pose>0.03744 0.005223 0 3.14159 -0 0</pose>
          <mass>0.220991</mass>
          <inertia>
            <ixx>6.369e-05</ixx>
            <ixy>-2.292e-05</ixy>
            <ixz>0</ixz>
            <iyy>0.0001677</iyy>
            <iyz>0</iyz>
            <izz>0.0001834</izz>
          </inertia>
        </inertial>
        <collision name='wx250s/lower_forearm_link_collision'>
          <pose>0 0 0 3.14159 -0 0</pose>
          <geometry>
            <mesh>
              <scale>0.001 0.001 0.001</scale>
              <uri>/home/interbotix_ws/src/interbotix_ros_manipulators/interbotix_ros_xsarms/interbotix_xsarm_descriptions/meshes/wx250s_meshes/wx250s_5_lower_forearm.stl</uri>
            </mesh>
          </geometry>
          <surface>
            <contact>
              <ode/>
            </contact>
            <friction>
              <ode/>
              <torsional>
                <ode/>
              </torsional>
            </friction>
            <bounce/>
          </surface>
          <max_contacts>10</max_contacts>
        </collision>
        <visual name='wx250s/lower_forearm_link_visual'>
          <pose>0 0 0 3.14159 -0 0</pose>
          <geometry>
            <mesh>
              <scale>0.001 0.001 0.001</scale>
              <uri>/home/interbotix_ws/src/interbotix_ros_manipulators/interbotix_ros_xsarms/interbotix_xsarm_descriptions/meshes/wx250s_meshes/wx250s_5_lower_forearm.stl</uri>
            </mesh>
          </geometry>
          <material>
            <script>
              <name>Custom/Interbotix</name>
              <uri>file://media/materials/scripts/gazebo.material</uri>
            </script>
          </material>
        </visual>
        <velocity_decay>
          <linear>0.1</linear>
          <angular>0.1</angular>
        </velocity_decay>
        <self_collide>0</self_collide>
        <enable_wind>0</enable_wind>
        <kinematic>0</kinematic>
      </link>
      <joint name='wrist_angle' type='revolute'>
        <pose relative_to='wx250s/lower_forearm_link'>0.075 0 0 0 -0 0</pose>
        <parent>wx250s/lower_forearm_link</parent>
        <child>wx250s/wrist_link</child>
        <axis>
          <xyz>0 1 0</xyz>
          <limit>
            <lower>-1.74533</lower>
            <upper>2.14675</upper>
            <effort>5</effort>
            <velocity>3.14159</velocity>
          </limit>
          <dynamics>
            <damping>0</damping>
            <friction>0.1</friction>
            <spring_reference>0</spring_reference>
            <spring_stiffness>0</spring_stiffness>
          </dynamics>
        </axis>
      </joint>
      <link name='wx250s/wrist_link'>
        <pose relative_to='wrist_angle'>0 0 0 0 -0 0</pose>
        <inertial>
          <pose>0.04236 -1.1e-05 0.010577 0 -0 1.5708</pose>
          <mass>0.084957</mass>
          <inertia>
            <ixx>3.082e-05</ixx>
            <ixy>1.91e-08</ixy>
            <ixz>2.3e-09</ixz>
            <iyy>2.822e-05</iyy>
            <iyz>2.5481e-06</iyz>
            <izz>3.152e-05</izz>
          </inertia>
        </inertial>
        <collision name='wx250s/wrist_link_collision'>
          <pose>0 0 0 0 -0 1.5708</pose>
          <geometry>
            <mesh>
              <scale>0.001 0.001 0.001</scale>
              <uri>/home/interbotix_ws/src/interbotix_ros_manipulators/interbotix_ros_xsarms/interbotix_xsarm_descriptions/meshes/wx250s_meshes/wx250s_6_wrist.stl</uri>
            </mesh>
          </geometry>
          <surface>
            <contact>
              <ode/>
            </contact>
            <friction>
              <ode/>
              <torsional>
                <ode/>
              </torsional>
            </friction>
            <bounce/>
          </surface>
          <max_contacts>10</max_contacts>
        </collision>
        <visual name='wx250s/wrist_link_visual'>
          <pose>0 0 0 0 -0 1.5708</pose>
          <geometry>
            <mesh>
              <scale>0.001 0.001 0.001</scale>
              <uri>/home/interbotix_ws/src/interbotix_ros_manipulators/interbotix_ros_xsarms/interbotix_xsarm_descriptions/meshes/wx250s_meshes/wx250s_6_wrist.stl</uri>
            </mesh>
          </geometry>
          <material>
            <script>
              <name>Custom/Interbotix</name>
              <uri>file://media/materials/scripts/gazebo.material</uri>
            </script>
          </material>
        </visual>
        <velocity_decay>
          <linear>0.1</linear>
          <angular>0.1</angular>
        </velocity_decay>
        <self_collide>0</self_collide>
        <enable_wind>0</enable_wind>
        <kinematic>0</kinematic>
      </link>
      <joint name='wrist_rotate' type='revolute'>
        <pose relative_to='wx250s/wrist_link'>0.065 0 0 0 -0 0</pose>
        <parent>wx250s/wrist_link</parent>
        <child>wx250s/gripper_link</child>
        <axis>
          <xyz>1 0 0</xyz>
          <limit>
            <lower>-3.14158</lower>
            <upper>3.14158</upper>
            <effort>1</effort>
            <velocity>3.14159</velocity>
          </limit>
          <dynamics>
            <damping>0</damping>
            <friction>0.1</friction>
            <spring_reference>0</spring_reference>
            <spring_stiffness>0</spring_stiffness>
          </dynamics>
        </axis>
      </joint>
      <link name='wx250s/gripper_link'>
        <pose relative_to='wrist_rotate'>0 0 0 0 -0 0</pose>
        <inertial>
          <pose>0.021631 0 0.01141 0 -0 1.5708</pose>
          <mass>0.072885</mass>
          <inertia>
            <ixx>2.537e-05</ixx>
            <ixy>0</ixy>
            <ixz>0</ixz>
            <iyy>1.836e-05</iyy>
            <iyz>4.34e-07</iyz>
            <izz>1.674e-05</izz>
          </inertia>
        </inertial>
        <collision name='wx250s/gripper_link_collision'>
          <pose>-0.02 0 0 0 -0 1.5708</pose>
          <geometry>
            <mesh>
              <scale>0.001 0.001 0.001</scale>
              <uri>/home/interbotix_ws/src/interbotix_ros_manipulators/interbotix_ros_xsarms/interbotix_xsarm_descriptions/meshes/wx250s_meshes/wx250s_7_gripper.stl</uri>
            </mesh>
          </geometry>
          <surface>
            <contact>
              <ode/>
            </contact>
            <friction>
              <ode/>
              <torsional>
                <ode/>
              </torsional>
            </friction>
            <bounce/>
          </surface>
          <max_contacts>10</max_contacts>
        </collision>
        <visual name='wx250s/gripper_link_visual'>
          <pose>-0.02 0 0 0 -0 1.5708</pose>
          <geometry>
            <mesh>
              <scale>0.001 0.001 0.001</scale>
              <uri>/home/interbotix_ws/src/interbotix_ros_manipulators/interbotix_ros_xsarms/interbotix_xsarm_descriptions/meshes/wx250s_meshes/wx250s_7_gripper.stl</uri>
            </mesh>
          </geometry>
          <material>
            <script>
              <name>Custom/Interbotix</name>
              <uri>file://media/materials/scripts/gazebo.material</uri>
            </script>
          </material>
        </visual>
        <velocity_decay>
          <linear>0.1</linear>
          <angular>0.1</angular>
        </velocity_decay>
        <self_collide>0</self_collide>
        <enable_wind>0</enable_wind>
        <kinematic>0</kinematic>
      </link>
      <joint name='ee_arm' type='revolute'>
        <pose relative_to='wx250s/gripper_link'>0.043 0 0 0 -0 0</pose>
        <parent>wx250s/gripper_link</parent>
        <child>wx250s/ee_arm_link</child>
        <axis>
          <limit>
            <lower>0</lower>
            <upper>0</upper>
          </limit>
          <dynamics>
            <damping>0</damping>
            <friction>0</friction>
            <spring_reference>0</spring_reference>
            <spring_stiffness>0</spring_stiffness>
          </dynamics>
          <xyz>0 0 1</xyz>
        </axis>
        <physics>
          <ode>
            <limit>
              <cfm>0</cfm>
              <erp>0.2</erp>
            </limit>
          </ode>
        </physics>
      </joint>
      <link name='wx250s/ee_arm_link'>
        <pose relative_to='ee_arm'>0 0 0 0 -0 0</pose>
        <inertial>
          <pose>0 0 0 0 -0 0</pose>
          <mass>0.001</mass>
          <inertia>
            <ixx>0.001</ixx>
            <ixy>0</ixy>
            <ixz>0</ixz>
            <iyy>0.001</iyy>
            <iyz>0</iyz>
            <izz>0.001</izz>
          </inertia>
        </inertial>
        <self_collide>0</self_collide>
        <enable_wind>0</enable_wind>
        <kinematic>0</kinematic>
      </link>
      <joint name='gripper' type='revolute'>
        <pose relative_to='wx250s/ee_arm_link'>0.0055 0 0 0 -0 0</pose>
        <parent>wx250s/ee_arm_link</parent>
        <child>wx250s/gripper_prop_link</child>
        <axis>
          <xyz>1 0 0</xyz>
          <limit>
            <effort>1</effort>
            <velocity>3.14159</velocity>
            <lower>-1e+16</lower>
            <upper>1e+16</upper>
          </limit>
          <dynamics>
            <damping>0</damping>
            <friction>0.1</friction>
            <spring_reference>0</spring_reference>
            <spring_stiffness>0</spring_stiffness>
          </dynamics>
        </axis>
      </joint>
      <link name='wx250s/gripper_prop_link'>
        <pose relative_to='gripper'>0 0 0 0 -0 0</pose>
        <inertial>
          <pose>0.000846 -2e-06 4.2e-05 0 -0 1.5708</pose>
          <mass>0.00434</mass>
          <inertia>
            <ixx>5.923e-07</ixx>
            <ixy>0</ixy>
            <ixz>3.195e-07</ixz>
            <iyy>1.1156e-06</iyy>
            <iyz>-4e-10</iyz>
            <izz>5.743e-07</izz>
          </inertia>
        </inertial>
        <collision name='wx250s/gripper_prop_link_collision'>
          <pose>-0.0685 0 0 0 -0 1.5708</pose>
          <geometry>
            <mesh>
              <scale>0.001 0.001 0.001</scale>
              <uri>/home/interbotix_ws/src/interbotix_ros_manipulators/interbotix_ros_xsarms/interbotix_xsarm_descriptions/meshes/wx250s_meshes/wx250s_8_gripper_prop.stl</uri>
            </mesh>
          </geometry>
          <surface>
            <contact>
              <ode/>
            </contact>
            <friction>
              <ode/>
              <torsional>
                <ode/>
              </torsional>
            </friction>
            <bounce/>
          </surface>
          <max_contacts>10</max_contacts>
        </collision>
        <visual name='wx250s/gripper_prop_link_visual'>
          <pose>-0.0685 0 0 0 -0 1.5708</pose>
          <geometry>
            <mesh>
              <scale>0.001 0.001 0.001</scale>
              <uri>/home/interbotix_ws/src/interbotix_ros_manipulators/interbotix_ros_xsarms/interbotix_xsarm_descriptions/meshes/wx250s_meshes/wx250s_8_gripper_prop.stl</uri>
            </mesh>
          </geometry>
          <material>
            <script>
              <name>Custom/Interbotix</name>
              <uri>file://media/materials/scripts/gazebo.material</uri>
            </script>
          </material>
        </visual>
        <velocity_decay>
          <linear>0.1</linear>
          <angular>0.1</angular>
        </velocity_decay>
        <self_collide>0</self_collide>
        <enable_wind>0</enable_wind>
        <kinematic>0</kinematic>
      </link>
      <joint name='gripper_bar' type='revolute'>
        <pose relative_to='wx250s/ee_arm_link'>0 0 0 0 -0 0</pose>
        <parent>wx250s/ee_arm_link</parent>
        <child>wx250s/gripper_bar_link</child>
        <axis>
          <limit>
            <lower>0</lower>
            <upper>0</upper>
          </limit>
          <dynamics>
            <damping>0</damping>
            <friction>0</friction>
            <spring_reference>0</spring_reference>
            <spring_stiffness>0</spring_stiffness>
          </dynamics>
          <xyz>0 0 1</xyz>
        </axis>
        <physics>
          <ode>
            <limit>
              <cfm>0</cfm>
              <erp>0.2</erp>
            </limit>
          </ode>
        </physics>
      </joint>
      <link name='wx250s/gripper_bar_link'>
        <pose relative_to='gripper_bar'>0 0 0 0 -0 0</pose>
        <inertial>
          <pose>0.009687 1e-06 0.004962 0 -0 1.5708</pose>
          <mass>0.034199</mass>
          <inertia>
            <ixx>7.4125e-06</ixx>
            <ixy>-8e-10</ixy>
            <ixz>-6e-10</ixz>
            <iyy>2.843e-05</iyy>
            <iyz>-1.3889e-06</iyz>
            <izz>2.86e-05</izz>
          </inertia>
        </inertial>
        <collision name='wx250s/gripper_bar_link_collision'>
          <pose>-0.063 0 0 0 -0 1.5708</pose>
          <geometry>
            <mesh>
              <scale>0.001 0.001 0.001</scale>
              <uri>/home/interbotix_ws/src/interbotix_ros_manipulators/interbotix_ros_xsarms/interbotix_xsarm_descriptions/meshes/wx250s_meshes/wx250s_9_gripper_bar.stl</uri>
            </mesh>
          </geometry>
          <surface>
            <contact>
              <ode/>
            </contact>
            <friction>
              <ode/>
              <torsional>
                <ode/>
              </torsional>
            </friction>
            <bounce/>
          </surface>
          <max_contacts>10</max_contacts>
        </collision>
        <visual name='wx250s/gripper_bar_link_visual'>
          <pose>-0.063 0 0 0 -0 1.5708</pose>
          <geometry>
            <mesh>
              <scale>0.001 0.001 0.001</scale>
              <uri>/home/interbotix_ws/src/interbotix_ros_manipulators/interbotix_ros_xsarms/interbotix_xsarm_descriptions/meshes/wx250s_meshes/wx250s_9_gripper_bar.stl</uri>
            </mesh>
          </geometry>
          <material>
            <script>
              <name>Custom/Interbotix</name>
              <uri>file://media/materials/scripts/gazebo.material</uri>
            </script>
          </material>
        </visual>
        <self_collide>0</self_collide>
        <enable_wind>0</enable_wind>
        <kinematic>0</kinematic>
      </link>
      <joint name='ee_bar' type='revolute'>
        <pose relative_to='wx250s/gripper_bar_link'>0.023 0 0 0 -0 0</pose>
        <parent>wx250s/gripper_bar_link</parent>
        <child>wx250s/fingers_link</child>
        <axis>
          <limit>
            <lower>0</lower>
            <upper>0</upper>
          </limit>
          <dynamics>
            <damping>0</damping>
            <friction>0</friction>
            <spring_reference>0</spring_reference>
            <spring_stiffness>0</spring_stiffness>
          </dynamics>
          <xyz>0 0 1</xyz>
        </axis>
        <physics>
          <ode>
            <limit>
              <cfm>0</cfm>
              <erp>0.2</erp>
            </limit>
          </ode>
        </physics>
      </joint>
      <link name='wx250s/fingers_link'>
        <pose relative_to='ee_bar'>0 0 0 0 -0 0</pose>
        <inertial>
          <pose>0 0 0 0 -0 0</pose>
          <mass>0.001</mass>
          <inertia>
            <ixx>0.001</ixx>
            <ixy>0</ixy>
            <ixz>0</ixz>
            <iyy>0.001</iyy>
            <iyz>0</iyz>
            <izz>0.001</izz>
          </inertia>
        </inertial>
        <self_collide>0</self_collide>
        <enable_wind>0</enable_wind>
        <kinematic>0</kinematic>
      </link>
      <joint name='ee_gripper' type='revolute'>
        <pose relative_to='wx250s/fingers_link'>0.027575 0 0 0 -0 0</pose>
        <parent>wx250s/fingers_link</parent>
        <child>wx250s/ee_gripper_link</child>
        <axis>
          <limit>
            <lower>0</lower>
            <upper>0</upper>
          </limit>
          <dynamics>
            <damping>0</damping>
            <friction>0</friction>
            <spring_reference>0</spring_reference>
            <spring_stiffness>0</spring_stiffness>
          </dynamics>
          <xyz>0 0 1</xyz>
        </axis>
        <physics>
          <ode>
            <limit>
              <cfm>0</cfm>
              <erp>0.2</erp>
            </limit>
          </ode>
        </physics>
      </joint>
      <link name='wx250s/ee_gripper_link'>
        <pose relative_to='ee_gripper'>0 0 0 0 -0 0</pose>
        <inertial>
          <pose>0 0 0 0 -0 0</pose>
          <mass>0.001</mass>
          <inertia>
            <ixx>0.001</ixx>
            <ixy>0</ixy>
            <ixz>0</ixz>
            <iyy>0.001</iyy>
            <iyz>0</iyz>
            <izz>0.001</izz>
          </inertia>
        </inertial>
        <self_collide>0</self_collide>
        <enable_wind>0</enable_wind>
        <kinematic>0</kinematic>
      </link>
      <joint name='left_finger' type='prismatic'>
        <pose relative_to='wx250s/fingers_link'>0 0 0 0 -0 0</pose>
        <parent>wx250s/fingers_link</parent>
        <child>wx250s/left_finger_link</child>
        <axis>
          <xyz>0 1 0</xyz>
          <limit>
            <lower>0.015</lower>
            <upper>0.037</upper>
            <effort>5</effort>
            <velocity>1</velocity>
          </limit>
          <dynamics>
            <damping>0</damping>
            <friction>0.1</friction>
            <spring_reference>0</spring_reference>
            <spring_stiffness>0</spring_stiffness>
          </dynamics>
        </axis>
      </joint>
      <link name='wx250s/left_finger_link'>
        <pose relative_to='left_finger'>0 0 0 0 -0 0</pose>
        <inertial>
          <pose>0.013816 0 0 0 0 -1.5708</pose>
          <mass>0.016246</mass>
          <inertia>
            <ixx>4.731e-06</ixx>
            <ixy>-4.56e-07</ixy>
            <ixz>0</ixz>
            <iyy>1.5506e-06</iyy>
            <iyz>0</iyz>
            <izz>3.7467e-06</izz>
          </inertia>
        </inertial>
        <collision name='wx250s/left_finger_link_collision'>
          <pose>0 0.005 0 0 -0 3.14159</pose>
          <geometry>
            <mesh>
              <scale>0.001 0.001 0.001</scale>
              <uri>/home/interbotix_ws/src/interbotix_ros_manipulators/interbotix_ros_xsarms/interbotix_xsarm_descriptions/meshes/wx250s_meshes/wx250s_10_gripper_finger.stl</uri>
            </mesh>
          </geometry>
          <surface>
            <contact>
              <ode/>
            </contact>
            <friction>
              <ode/>
              <torsional>
                <ode/>
              </torsional>
            </friction>
            <bounce/>
          </surface>
          <max_contacts>10</max_contacts>
        </collision>
        <sensor name='left_tip_contact' type='contact'>
          <contact>
            <collision>wx250s/left_finger_link_collision</collision>
            <topic>__default_topic__</topic>
          </contact>
          <update_rate>100</update_rate>
          <plugin name='left_bumper' filename='libgazebo_ros_bumper.so'>
            <robotNamespace>/wx250s</robotNamespace>
            <bumperTopicName>left_tip_contact</bumperTopicName>
            <frameName>wx250s/left_finger_link</frameName>
          </plugin>
        </sensor>
        <visual name='wx250s/left_finger_link_visual'>
          <pose>0 0.005 0 0 -0 3.14159</pose>
          <geometry>
            <mesh>
              <scale>0.001 0.001 0.001</scale>
              <uri>/home/interbotix_ws/src/interbotix_ros_manipulators/interbotix_ros_xsarms/interbotix_xsarm_descriptions/meshes/wx250s_meshes/wx250s_10_gripper_finger.stl</uri>
            </mesh>
          </geometry>
          <material>
            <script>
              <name>Custom/Interbotix</name>
              <uri>file://media/materials/scripts/gazebo.material</uri>
            </script>
          </material>
        </visual>
        <velocity_decay>
          <linear>0.1</linear>
          <angular>0.1</angular>
        </velocity_decay>
        <self_collide>0</self_collide>
        <enable_wind>0</enable_wind>
        <kinematic>0</kinematic>
      </link>
      <joint name='right_finger' type='prismatic'>
        <pose relative_to='wx250s/fingers_link'>0 0 0 0 -0 0</pose>
        <parent>wx250s/fingers_link</parent>
        <child>wx250s/right_finger_link</child>
        <axis>
          <xyz>0 1 0</xyz>
          <limit>
            <lower>-0.037</lower>
            <upper>-0.015</upper>
            <effort>5</effort>
            <velocity>1</velocity>
          </limit>
          <dynamics>
            <damping>0</damping>
            <friction>0.1</friction>
            <spring_reference>0</spring_reference>
            <spring_stiffness>0</spring_stiffness>
          </dynamics>
        </axis>
      </joint>
      <link name='wx250s/right_finger_link'>
        <pose relative_to='right_finger'>0 0 0 0 -0 0</pose>
        <inertial>
          <pose>0.013816 0 0 3.14159 -0 -1.5708</pose>
          <mass>0.016246</mass>
          <inertia>
            <ixx>4.731e-06</ixx>
            <ixy>4.56e-07</ixy>
            <ixz>0</ixz>
            <iyy>1.5506e-06</iyy>
            <iyz>0</iyz>
            <izz>3.7467e-06</izz>
          </inertia>
        </inertial>
        <collision name='wx250s/right_finger_link_collision'>
          <pose>0 -0.005 0 3.14159 -0 3.14159</pose>
          <geometry>
            <mesh>
              <scale>0.001 0.001 0.001</scale>
              <uri>/home/interbotix_ws/src/interbotix_ros_manipulators/interbotix_ros_xsarms/interbotix_xsarm_descriptions/meshes/wx250s_meshes/wx250s_10_gripper_finger.stl</uri>
            </mesh>
          </geometry>
          <surface>
            <contact>
              <ode/>
            </contact>
            <friction>
              <ode/>
              <torsional>
                <ode/>
              </torsional>
            </friction>
            <bounce/>
          </surface>
          <max_contacts>10</max_contacts>
        </collision>
        <sensor name='right_tip_contact' type='contact'>
          <contact>
            <collision>wx250s/right_finger_link_collision</collision>
            <topic>__default_topic__</topic>
          </contact>
          <update_rate>100</update_rate>
          <plugin name='right_bumper' filename='libgazebo_ros_bumper.so'>
            <robotNamespace>/wx250s</robotNamespace>
            <bumperTopicName>right_tip_contact</bumperTopicName>
            <frameName>wx250s/right_finger_link</frameName>
          </plugin>
        </sensor>
        <visual name='wx250s/right_finger_link_visual'>
          <pose>0 -0.005 0 3.14159 -0 3.14159</pose>
          <geometry>
            <mesh>
              <scale>0.001 0.001 0.001</scale>
              <uri>/home/interbotix_ws/src/interbotix_ros_manipulators/interbotix_ros_xsarms/interbotix_xsarm_descriptions/meshes/wx250s_meshes/wx250s_10_gripper_finger.stl</uri>
            </mesh>
          </geometry>
          <material>
            <script>
              <name>Custom/Interbotix</name>
              <uri>file://media/materials/scripts/gazebo.material</uri>
            </script>
          </material>
        </visual>
        <velocity_decay>
          <linear>0.1</linear>
          <angular>0.1</angular>
        </velocity_decay>
        <self_collide>0</self_collide>
        <enable_wind>0</enable_wind>
        <kinematic>0</kinematic>
      </link>
      <plugin name='gazebo_ros_control' filename='libgazebo_ros_control.so'>
        <robotSimType>gazebo_ros_control/DefaultRobotHWSim</robotSimType>
        <legacyModeNS>1</legacyModeNS>
        <robotNamespace>/wx250s/</robotNamespace>
      </plugin>
      <pose>0 0 0 0 -0 0</pose>
    </model>
    <model name='table'>
      <joint name='fixed' type='fixed'>
        <pose relative_to='__model__'>0 0 0 0 -0 0</pose>
        <parent>world</parent>
        <child>table/link</child>
      </joint>
      <link name='table/link'>
        <collision name='surface'>
          <pose>0 0 1 0 -0 0</pose>
          <geometry>
            <box>
              <size>1.5 0.8 0.03</size>
            </box>
          </geometry>
          <surface>
            <friction>
              <ode>
                <mu>0.6</mu>
                <mu2>0.6</mu2>
              </ode>
              <torsional>
                <ode/>
              </torsional>
            </friction>
            <contact>
              <ode/>
            </contact>
            <bounce/>
          </surface>
          <max_contacts>10</max_contacts>
        </collision>
        <visual name='visual1'>
          <pose>0 0 1 0 -0 0</pose>
          <geometry>
            <box>
              <size>1.5 0.8 0.03</size>
            </box>
          </geometry>
          <material>
            <script>
              <uri>file://media/materials/scripts/gazebo.material</uri>
              <name>Gazebo/Wood</name>
            </script>
          </material>
        </visual>
        <collision name='front_left_leg_collision'>
          <pose>0.68 0.38 0.5 0 -0 0</pose>
          <geometry>
            <cylinder>
              <radius>0.02</radius>
              <length>1</length>
            </cylinder>
          </geometry>
          <max_contacts>10</max_contacts>
          <surface>
            <contact>
              <ode/>
            </contact>
            <bounce/>
            <friction>
              <torsional>
                <ode/>
              </torsional>
              <ode/>
            </friction>
          </surface>
        </collision>
        <visual name='front_left_leg_visual'>
          <pose>0.68 0.38 0.5 0 -0 0</pose>
          <geometry>
            <cylinder>
              <radius>0.02</radius>
              <length>1</length>
            </cylinder>
          </geometry>
          <material>
            <script>
              <uri>file://media/materials/scripts/gazebo.material</uri>
              <name>Gazebo/Grey</name>
            </script>
          </material>
        </visual>
        <collision name='front_right_leg_collision'>
          <pose>0.68 -0.38 0.5 0 -0 0</pose>
          <geometry>
            <cylinder>
              <radius>0.02</radius>
              <length>1</length>
            </cylinder>
          </geometry>
          <max_contacts>10</max_contacts>
          <surface>
            <contact>
              <ode/>
            </contact>
            <bounce/>
            <friction>
              <torsional>
                <ode/>
              </torsional>
              <ode/>
            </friction>
          </surface>
        </collision>
        <visual name='front_right_leg_visual'>
          <pose>0.68 -0.38 0.5 0 -0 0</pose>
          <geometry>
            <cylinder>
              <radius>0.02</radius>
              <length>1</length>
            </cylinder>
          </geometry>
          <material>
            <script>
              <uri>file://media/materials/scripts/gazebo.material</uri>
              <name>Gazebo/Grey</name>
            </script>
          </material>
        </visual>
        <collision name='back_right_leg_collision'>
          <pose>-0.68 -0.38 0.5 0 -0 0</pose>
          <geometry>
            <cylinder>
              <radius>0.02</radius>
              <length>1</length>
            </cylinder>
          </geometry>
          <max_contacts>10</max_contacts>
          <surface>
            <contact>
              <ode/>
            </contact>
            <bounce/>
            <friction>
              <torsional>
                <ode/>
              </torsional>
              <ode/>
            </friction>
          </surface>
        </collision>
        <visual name='back_right_leg_visual'>
          <pose>-0.68 -0.38 0.5 0 -0 0</pose>
          <geometry>
            <cylinder>
              <radius>0.02</radius>
              <length>1</length>
            </cylinder>
          </geometry>
          <material>
            <script>
              <uri>file://media/materials/scripts/gazebo.material</uri>
              <name>Gazebo/Grey</name>
            </script>
          </material>
        </visual>
        <collision name='back_left_leg_collision'>
          <pose>-0.68 0.38 0.5 0 -0 0</pose>
          <geometry>
            <cylinder>
              <radius>0.02</radius>
              <length>1</length>
            </cylinder>
          </geometry>
          <max_contacts>10</max_contacts>
          <surface>
            <contact>
              <ode/>
            </contact>
            <bounce/>
            <friction>
              <torsional>
                <ode/>
              </torsional>
              <ode/>
            </friction>
          </surface>
        </collision>
        <visual name='back_left_leg_visual'>
          <pose>-0.68 0.38 0.5 0 -0 0</pose>
          <geometry>
            <cylinder>
              <radius>0.02</radius>
              <length>1</length>
            </cylinder>
          </geometry>
          <material>
            <script>
              <uri>file://media/materials/scripts/gazebo.material</uri>
              <name>Gazebo/Grey</name>
            </script>
          </material>
        </visual>
        <self_collide>0</self_collide>
        <enable_wind>0</enable_wind>
        <kinematic>0</kinematic>
        <inertial>
          <pose>0 0 0 0 -0 0</pose>
          <inertia>
            <ixx>1</ixx>
            <ixy>0</ixy>
            <ixz>0</ixz>
            <iyy>1</iyy>
            <iyz>0</iyz>
            <izz>1</izz>
          </inertia>
          <mass>1</mass>
        </inertial>
      </link>
      <pose>0 0 0 0 -0 0</pose>
    </model>
    <state world_name='default'>
      <sim_time>387 27000000</sim_time>
      <real_time>24 563090980</real_time>
      <wall_time>1750058760 207845446</wall_time>
      <iterations>21374</iterations>
      <model name='Diamond_Visions_Scissors_Red'>
        <pose>0.139713 0.20909 1.01475 -0.005753 -0.018303 0.038289</pose>
        <scale>1 1 1</scale>
        <link name='link_0'>
          <pose>0.139713 0.20909 1.01475 -0.005753 -0.018303 0.038289</pose>
          <velocity>1e-06 1e-06 -0.009289 0 -0 0</velocity>
          <acceleration>0 0 -9.8 -0 -0 -0</acceleration>
          <wrench>0 0 -0.098 0 -0 0</wrench>
        </link>
      </model>
      <model name='OXO_Cookie_Spatula'>
        <pose>-0.414382 0.02258 1.0146 -0.017239 -0.007447 -2.83833</pose>
        <scale>1 1 1</scale>
        <link name='link_0'>
          <pose>-0.414382 0.02258 1.0146 -0.017239 -0.007447 -2.83833</pose>
          <velocity>-1e-06 -0 6.1e-05 -1e-06 4e-06 0</velocity>
          <acceleration>-0.001179 -0.00028 0.061112 -0.000583 0.004288 0</acceleration>
          <wrench>-1.2e-05 -3e-06 0.000611 0 -0 0</wrench>
        </link>
      </model>
      <model name='Oven'>
        <pose>-0.006011 -0.778291 0.001796 0 -0 1.56303</pose>
        <scale>1 1 1</scale>
        <link name='base_link'>
          <pose>-0.006011 -0.778291 0.001796 0 -0 1.56303</pose>
          <velocity>0 0 0 0 -0 0</velocity>
          <acceleration>0 0 0 0 -0 0</acceleration>
          <wrench>0 0 0 0 -0 0</wrench>
        </link>
      </model>
      <model name='Tag_Dishtowel_Dobby_Stripe_Blue_18_x_26'>
        <pose>0.286723 0.115251 1.01466 0.00408 0.01048 2.06937</pose>
        <scale>1 1 1</scale>
        <link name='link_0'>
          <pose>0.286723 0.115251 1.01466 0.00408 0.01048 2.06937</pose>
          <velocity>1e-06 0 -0.000124 -3e-06 -2.4e-05 0</velocity>
          <acceleration>0 0 -9.8 0 -0 0</acceleration>
          <wrench>0 0 -0.098 0 -0 0</wrench>
        </link>
      </model>
      <model name='Target_Basket_Medium'>
        <pose>0.184187 -0.286257 1.01371 -0.000784 0.013141 1.17611</pose>
        <scale>1 1 1</scale>
        <link name='link_0'>
          <pose>0.184187 -0.286257 1.01371 -0.000784 0.013141 1.17611</pose>
          <velocity>0 0 0 0 -0 0</velocity>
          <acceleration>0.015625 -0.005204 8.508 0.061305 -0.656005 -0.01225</acceleration>
          <wrench>0.015625 -0.005204 8.508 0 -0 0</wrench>
        </link>
      </model>
      <model name='Threshold_Porcelain_Coffee_Mug_All_Over_Bead_White'>
        <pose>-0.361606 0.194836 1.01465 -0.005448 -0.008153 0.107712</pose>
        <scale>1 1 1</scale>
        <link name='link_0'>
          <pose>-0.361606 0.194836 1.01465 -0.005448 -0.008153 0.107712</pose>
          <velocity>1e-06 1e-06 -0.009679 2e-06 -0 0</velocity>
          <acceleration>0 0 -9.8 0 -0 0</acceleration>
          <wrench>0 0 -0.098 0 -0 0</wrench>
        </link>
      </model>
      <model name='Threshold_Porcelain_Serving_Bowl_Coupe_White'>
        <pose>-0.165796 0.144996 1.01456 -0.009153 -0.007987 0.029394</pose>
        <scale>1 1 1</scale>
        <link name='link_0'>
          <pose>-0.165796 0.144996 1.01456 -0.009153 -0.007987 0.029394</pose>
          <velocity>-1e-06 -0 0.009972 2e-06 -8e-06 -0</velocity>
          <acceleration>-0.001174 -0.000279 9.97242 0.002075 -0.007582 8e-06</acceleration>
          <wrench>-1.2e-05 -3e-06 0.099724 0 -0 0</wrench>
        </link>
      </model>
      <model name='Vanity'>
        <pose>-0.026233 0.739904 0.230121 0 -0 0</pose>
        <scale>1 1 1</scale>
        <link name='base_link'>
          <pose>-0.026233 0.739904 0.230121 0 -0 0</pose>
          <velocity>0 0 0 0 -0 0</velocity>
          <acceleration>0 0 0 0 -0 0</acceleration>
          <wrench>0 0 0 0 -0 0</wrench>
        </link>
      </model>
      <model name='freecam'>
        <pose>2.09029 1.28989 2.28609 -0 0.47564 -2.65341</pose>
        <scale>1 1 1</scale>
        <link name='camera_link'>
          <pose>2.09029 1.28989 2.28609 -0 0.47564 -2.65341</pose>
          <velocity>0 0 0 0 -0 0</velocity>
          <acceleration>0 0 0 0 -0 0</acceleration>
          <wrench>0 0 0 0 -0 0</wrench>
        </link>
      </model>
      <model name='ground_plane'>
        <pose>0 0 0 0 -0 0</pose>
        <scale>1 1 1</scale>
        <link name='link'>
          <pose>0 0 0 0 -0 0</pose>
          <velocity>0 0 0 0 -0 0</velocity>
          <acceleration>0 0 0 0 -0 0</acceleration>
          <wrench>0 0 0 0 -0 0</wrench>
        </link>
      </model>
      <model name='table'>
        <pose>0 0 0 0 -0 0</pose>
        <scale>1 1 1</scale>
        <link name='table/link'>
          <pose>0 0 0 0 -0 0</pose>
          <velocity>-0 -0 4e-06 0 -1e-06 0</velocity>
          <acceleration>-0.000129 -0.000109 0.007952 0.000693 -0.001879 1.8e-05</acceleration>
          <wrench>-0.000129 -0.000109 0.007952 0 -0 0</wrench>
        </link>
      </model>
      <model name='wx250s'>
        <pose>-0 -0 0 0 -0 0</pose>
        <scale>1 1 1</scale>
        <link name='wx250s/base_link'>
          <pose>0 -0 1.015 0 -0 0</pose>
          <velocity>-1e-06 -0 -4e-06 -9e-06 -4.7e-05 2e-06</velocity>
          <acceleration>-0.002502 0.00039 -0.009806 -0.064028 -0.051591 0.004028</acceleration>
          <wrench>-0.001348 0.00021 -0.005283 0 -0 0</wrench>
        </link>
        <link name='wx250s/ee_arm_link'>
          <pose>0.252455 -1.9e-05 1.362 -2.81029 1.54834 -2.81383</pose>
          <velocity>0.001017 0.000187 0.00336 0.002568 0.001117 4.6e-05</velocity>
          <acceleration>1.34814 0.249459 4.20668 2.25138 1.43222 -2.90816</acceleration>
          <wrench>0.001348 0.000249 0.004207 0 -0 0</wrench>
        </link>
        <link name='wx250s/ee_gripper_link'>
          <pose>0.251378 -0.000385 1.31143 -2.80981 1.54836 -2.81335</pose>
          <velocity>-0.00015 -7.5e-05 0.000185 -0.002006 0.000401 1e-05</velocity>
          <acceleration>-0.132364 -0.106715 0.311141 -3.09136 1.23791 0.184966</acceleration>
          <wrench>-0.000132 -0.000107 0.000311 0 -0 0</wrench>
        </link>
        <link name='wx250s/fingers_link'>
          <pose>0.251965 -0.000185 1.339 -2.80981 1.54836 -2.81334</pose>
          <velocity>0.000473 4.8e-05 0.001919 -0.002042 0.000453 1.4e-05</velocity>
          <acceleration>0.65725 0.048753 2.44406 -3.11695 1.30341 0.188612</acceleration>
          <wrench>0.000657 4.9e-05 0.002444 0 -0 0</wrench>
        </link>
        <link name='wx250s/gripper_bar_link'>
          <pose>0.252455 -1.9e-05 1.362 -2.80984 1.54835 -2.81337</pose>
          <velocity>0.000151 0.000106 0.000237 -0.003042 0.007648 0.000106</velocity>
          <acceleration>0.180926 0.161215 0.279767 -0.834189 -0.906711 3.03281</acceleration>
          <wrench>0.006187 0.005513 0.009568 0 -0 0</wrench>
        </link>
        <link name='wx250s/gripper_link'>
          <pose>0.253372 0.000292 1.405 -2.8102 1.54834 -2.81374</pose>
          <velocity>0.00027 9.8e-05 7.1e-05 0.001084 0.003666 0.00011</velocity>
          <acceleration>0.335638 0.263575 0.008489 -2.18696 -1.47865 -2.62843</acceleration>
          <wrench>0.024463 0.019211 0.000619 0 -0 0</wrench>
        </link>
        <link name='wx250s/gripper_prop_link'>
          <pose>0.252336 -5.9e-05 1.3565 -2.81067 1.54834 -2.81383</pose>
          <velocity>-1.7e-05 8e-05 0.000227 0.002606 0.001084 4.3e-05</velocity>
          <acceleration>0.068785 0.160922 0.348922 1.00161 0.733188 0.475247</acceleration>
          <wrench>0.000299 0.000698 0.001514 0 -0 0</wrench>
        </link>
        <link name='wx250s/left_finger_link'>
          <pose>0.252023 0.017001 1.33887 -2.80936 1.54836 -2.81289</pose>
          <velocity>-0.000115 -1.3e-05 0.00014 -0.001993 0.000517 0.000462</velocity>
          <acceleration>-0.088437 -0.047615 0.233193 1.87441 -0.181678 2.11052</acceleration>
          <wrench>-0.001437 -0.000774 0.003788 0 -0 0</wrench>
        </link>
        <link name='wx250s/lower_forearm_link'>
          <pose>0.184825 0.000553 1.44288 -0.007754 -0.369773 0.002992</pose>
          <velocity>0.000157 -4.9e-05 1e-05 0.000492 -0.000436 0.000177</velocity>
          <acceleration>0.285363 -0.063693 0.015731 2.77028 -1.00252 -0.671003</acceleration>
          <wrench>0.063063 -0.014076 0.003476 0 -0 0</wrench>
        </link>
        <link name='wx250s/right_finger_link'>
          <pose>0.251902 -0.018366 1.33914 -2.81013 1.54836 -2.81367</pose>
          <velocity>-1.8e-05 1.7e-05 0.000158 -0.002224 0.00053 -0.000444</velocity>
          <acceleration>0.045843 0.009226 0.242177 -2.55415 0.182448 -0.777388</acceleration>
          <wrench>0.000745 0.00015 0.003934 0 -0 0</wrench>
        </link>
        <link name='wx250s/shoulder_link'>
          <pose>-0 0 1.087 0 -1.1e-05 0.002993</pose>
          <velocity>1.8e-05 0 -1e-06 -3e-05 0.002798 9e-06</velocity>
          <acceleration>0.054456 0.005006 -0.002701 0.220419 -0.891535 3.10833</acceleration>
          <wrench>0.026187 0.002407 -0.001299 0 -0 0</wrench>
        </link>
        <link name='wx250s/upper_arm_link'>
          <pose>-0 -0 1.12565 0 -0.111377 0.002993</pose>
          <velocity>9.1e-05 -1e-06 4e-06 5.1e-05 0.000128 -7e-06</velocity>
          <acceleration>0.214592 0.001787 0.006005 0.036265 0.426043 -0.083933</acceleration>
          <wrench>0.092449 0.00077 0.002587 0 -0 0</wrench>
        </link>
        <link name='wx250s/upper_forearm_link'>
          <pose>0.021654 6.5e-05 1.37963 1e-06 -0.369774 0.002993</pose>
          <velocity>0.000144 -2.2e-05 7e-06 1e-06 -9e-05 -0.000103</velocity>
          <acceleration>0.269379 -0.031606 0.006265 0.965669 -0.165365 0.791117</acceleration>
          <wrench>0.063193 -0.007414 0.00147 0 -0 0</wrench>
        </link>
        <link name='wx250s/wrist_link'>
          <pose>0.254755 0.000762 1.46998 -2.81407 1.54832 -2.81396</pose>
          <velocity>0.000143 -3e-06 6.2e-05 0.000668 -0.000505 0.000262</velocity>
          <acceleration>0.308137 0.08061 0.058844 -1.79882 -0.482563 -1.85302</acceleration>
          <wrench>0.026178 0.006848 0.004999 0 -0 0</wrench>
        </link>
      </model>
      <light name='sun'>
        <pose>0 0 10 0 -0 0</pose>
      </light>
    </state>
    <gui fullscreen='0'>
      <camera name='user_camera'>
        <pose>-0.043891 -0.045553 3.32339 0 1.5138 0.005951</pose>
        <view_controller>orbit</view_controller>
        <projection_type>perspective</projection_type>
      </camera>
    </gui>
    <model name='Threshold_Porcelain_Coffee_Mug_All_Over_Bead_White'>
      <link name='link_0'>
        <visual name='visual'>
          <geometry>
            <mesh>
              <uri>/root/.gazebo/models/Threshold_Porcelain_Coffee_Mug_All_Over_Bead_White/meshes/model.obj</uri>
            </mesh>
          </geometry>
        </visual>
        <collision name='collision_0'>
          <geometry>
            <mesh>
              <uri>/root/.gazebo/models/Threshold_Porcelain_Coffee_Mug_All_Over_Bead_White/meshes/model.obj</uri>
            </mesh>
          </geometry>
          <max_contacts>10</max_contacts>
          <surface>
            <contact>
              <ode/>
            </contact>
            <bounce/>
            <friction>
              <torsional>
                <ode/>
              </torsional>
              <ode/>
            </friction>
          </surface>
        </collision>
        <self_collide>0</self_collide>
        <inertial>
          <pose>0 0 0 0 -0 0</pose>
          <inertia>
            <ixx>1</ixx>
            <ixy>0</ixy>
            <ixz>0</ixz>
            <iyy>1</iyy>
            <iyz>0</iyz>
            <izz>1</izz>
          </inertia>
          <mass>0.01</mass>
        </inertial>
        <enable_wind>0</enable_wind>
        <kinematic>0</kinematic>
      </link>
      <pose>-0.361609 0.194831 1.01465 -0.005449 -0.008158 0.10777</pose>
    </model>
    <model name='Threshold_Porcelain_Serving_Bowl_Coupe_White'>
      <link name='link_0'>
        <visual name='visual'>
          <geometry>
            <mesh>
              <uri>/root/.gazebo/models/Threshold_Porcelain_Serving_Bowl_Coupe_White/meshes/model.obj</uri>
            </mesh>
          </geometry>
        </visual>
        <collision name='collision_0'>
          <geometry>
            <mesh>
              <uri>/root/.gazebo/models/Threshold_Porcelain_Serving_Bowl_Coupe_White/meshes/model.obj</uri>
            </mesh>
          </geometry>
          <max_contacts>10</max_contacts>
          <surface>
            <contact>
              <ode/>
            </contact>
            <bounce/>
            <friction>
              <torsional>
                <ode/>
              </torsional>
              <ode/>
            </friction>
          </surface>
        </collision>
        <self_collide>0</self_collide>
        <inertial>
          <pose>0 0 0 0 -0 0</pose>
          <inertia>
            <ixx>1</ixx>
            <ixy>0</ixy>
            <ixz>0</ixz>
            <iyy>1</iyy>
            <iyz>0</iyz>
            <izz>1</izz>
          </inertia>
          <mass>0.01</mass>
        </inertial>
        <enable_wind>0</enable_wind>
        <kinematic>0</kinematic>
      </link>
      <pose>-0.165797 0.144996 1.01456 -0.009149 -0.007986 0.029443</pose>
    </model>
    <model name='Tag_Dishtowel_Dobby_Stripe_Blue_18_x_26'>
      <link name='link_0'>
        <visual name='visual'>
          <geometry>
            <mesh>
              <uri>/root/.gazebo/models/Tag_Dishtowel_Dobby_Stripe_Blue_18_x_26/meshes/model.obj</uri>
            </mesh>
          </geometry>
        </visual>
        <collision name='collision_0'>
          <geometry>
            <mesh>
              <uri>/root/.gazebo/models/Tag_Dishtowel_Dobby_Stripe_Blue_18_x_26/meshes/model.obj</uri>
            </mesh>
          </geometry>
          <max_contacts>10</max_contacts>
          <surface>
            <contact>
              <ode/>
            </contact>
            <bounce/>
            <friction>
              <torsional>
                <ode/>
              </torsional>
              <ode/>
            </friction>
          </surface>
        </collision>
        <self_collide>0</self_collide>
        <inertial>
          <pose>0 0 0 0 -0 0</pose>
          <inertia>
            <ixx>1</ixx>
            <ixy>0</ixy>
            <ixz>0</ixz>
            <iyy>1</iyy>
            <iyz>0</iyz>
            <izz>1</izz>
          </inertia>
          <mass>0.01</mass>
        </inertial>
        <enable_wind>0</enable_wind>
        <kinematic>0</kinematic>
      </link>
      <pose>0.286723 0.115251 1.01466 0.00408 0.01048 2.06937</pose>
    </model>
    <model name='Target_Basket_Medium'>
      <link name='link_0'>
        <visual name='visual'>
          <geometry>
            <mesh>
              <uri>/root/.gazebo/models/Target_Basket_Medium/meshes/model.obj</uri>
            </mesh>
          </geometry>
        </visual>
        <collision name='collision_0'>
          <geometry>
            <mesh>
              <uri>/root/.gazebo/models/Target_Basket_Medium/meshes/model.obj</uri>
            </mesh>
          </geometry>
          <max_contacts>10</max_contacts>
          <surface>
            <contact>
              <ode/>
            </contact>
            <bounce/>
            <friction>
              <torsional>
                <ode/>
              </torsional>
              <ode/>
            </friction>
          </surface>
        </collision>
        <self_collide>0</self_collide>
        <inertial>
          <pose>0 0 0 0 -0 0</pose>
          <inertia>
            <ixx>1</ixx>
            <ixy>0</ixy>
            <ixz>0</ixz>
            <iyy>1</iyy>
            <iyz>0</iyz>
            <izz>1</izz>
          </inertia>
          <mass>1</mass>
        </inertial>
        <enable_wind>0</enable_wind>
        <kinematic>0</kinematic>
      </link>
      <pose>0.184413 -0.303553 1.01371 -0.000788 0.013137 1.17345</pose>
    </model>
    <model name='Diamond_Visions_Scissors_Red'>
      <link name='link_0'>
        <visual name='visual'>
          <geometry>
            <mesh>
              <uri>/root/.gazebo/models/Diamond_Visions_Scissors_Red/meshes/model.obj</uri>
            </mesh>
          </geometry>
        </visual>
        <collision name='collision_0'>
          <geometry>
            <mesh>
              <uri>/root/.gazebo/models/Diamond_Visions_Scissors_Red/meshes/model.obj</uri>
            </mesh>
          </geometry>
          <max_contacts>10</max_contacts>
          <surface>
            <contact>
              <ode/>
            </contact>
            <bounce/>
            <friction>
              <torsional>
                <ode/>
              </torsional>
              <ode/>
            </friction>
          </surface>
        </collision>
        <self_collide>0</self_collide>
        <inertial>
          <pose>0 0 0 0 -0 0</pose>
          <inertia>
            <ixx>1</ixx>
            <ixy>0</ixy>
            <ixz>0</ixz>
            <iyy>1</iyy>
            <iyz>0</iyz>
            <izz>1</izz>
          </inertia>
          <mass>0.01</mass>
        </inertial>
        <enable_wind>0</enable_wind>
        <kinematic>0</kinematic>
      </link>
      <pose>0.139719 0.209095 1.01476 -0.005752 -0.018299 0.038277</pose>
    </model>
    <model name='OXO_Cookie_Spatula'>
      <link name='link_0'>
        <visual name='visual'>
          <geometry>
            <mesh>
              <uri>/root/.gazebo/models/OXO_Cookie_Spatula/meshes/model.obj</uri>
            </mesh>
          </geometry>
        </visual>
        <collision name='collision_0'>
          <geometry>
            <mesh>
              <uri>/root/.gazebo/models/OXO_Cookie_Spatula/meshes/model.obj</uri>
            </mesh>
          </geometry>
          <max_contacts>10</max_contacts>
          <surface>
            <contact>
              <ode/>
            </contact>
            <bounce/>
            <friction>
              <torsional>
                <ode/>
              </torsional>
              <ode/>
            </friction>
          </surface>
        </collision>
        <self_collide>0</self_collide>
        <inertial>
          <pose>0 0 0 0 -0 0</pose>
          <inertia>
            <ixx>1</ixx>
            <ixy>0</ixy>
            <ixz>0</ixz>
            <iyy>1</iyy>
            <iyz>0</iyz>
            <izz>1</izz>
          </inertia>
          <mass>0.01</mass>
        </inertial>
        <enable_wind>0</enable_wind>
        <kinematic>0</kinematic>
      </link>
      <pose>-0.414387 0.02258 1.0146 -0.017231 -0.007447 -2.83841</pose>
    </model>
    <model name='freecam'>
      <static>1</static>
      <pose>2.09029 1.28989 2.28609 -0 0.47564 -2.65341</pose>
      <link name='camera_link'>
        <sensor name='rgb_camera' type='camera'>
          <always_on>1</always_on>
          <update_rate>30</update_rate>
          <visualize>1</visualize>
          <camera>
            <horizontal_fov>1.047</horizontal_fov>
            <image>
              <width>640</width>
              <height>480</height>
              <format>R8G8B8</format>
            </image>
            <clip>
              <near>0.05</near>
              <far>10</far>
            </clip>
          </camera>
          <plugin name='gazebo_ros_camera' filename='libgazebo_ros_camera.so'>
            <robotNamespace>/freecam</robotNamespace>
            <cameraName>freecam</cameraName>
            <imageTopicName>image_raw</imageTopicName>
            <cameraInfoTopicName>camera_info</cameraInfoTopicName>
            <frameName>freecam_camera_link</frameName>
          </plugin>
        </sensor>
        <sensor name='depth_camera' type='depth'>
          <always_on>1</always_on>
          <update_rate>30</update_rate>
          <visualize>1</visualize>
          <camera>
            <horizontal_fov>1.047</horizontal_fov>
            <image>
              <width>640</width>
              <height>480</height>
              <format>R8G8B8</format>
            </image>
            <clip>
              <near>0.05</near>
              <far>10</far>
            </clip>
            <depth_camera>
              <output>depth</output>
            </depth_camera>
          </camera>
          <plugin name='gazebo_ros_depth_camera' filename='libgazebo_ros_depth_camera.so'>
            <robotNamespace>/freecam</robotNamespace>
            <cameraName>freecam_depth</cameraName>
            <imageTopicName>depth/image_raw</imageTopicName>
            <cameraInfoTopicName>depth/camera_info</cameraInfoTopicName>
            <frameName>freecam_camera_link</frameName>
            <depthImageTopicName>depth/image_raw</depthImageTopicName>
          </plugin>
        </sensor>
        <self_collide>0</self_collide>
        <enable_wind>0</enable_wind>
        <kinematic>0</kinematic>
      </link>
    </model>
    <model name='Vanity'>
      <static>1</static>
      <link name='base_link'>
        <visual name='visual_wood'>
          <geometry>
            <mesh>
              <scale>1 1 1</scale>
              <uri>/root/.gazebo/models/Vanity/meshes/vanity.dae</uri>
              <submesh>
                <name>Wood</name>
                <center>0</center>
              </submesh>
            </mesh>
          </geometry>
          <material>
            <diffuse>1 1 1 1</diffuse>
            <specular>1 1 1 1</specular>
            <pbr>
              <metal>
                <albedo_map>materials/textures/Wood_Albedo.png</albedo_map>
                <normal_map>materials/textures/Wood_Normal.png</normal_map>
                <roughness_map>materials/textures/Wood_Roughness.png</roughness_map>
              </metal>
            </pbr>
          </material>
        </visual>
        <visual name='visual_counter'>
          <geometry>
            <mesh>
              <scale>1 1 1</scale>
              <uri>/root/.gazebo/models/Vanity/meshes/vanity.dae</uri>
              <submesh>
                <name>Counter</name>
                <center>0</center>
              </submesh>
            </mesh>
          </geometry>
          <material>
            <diffuse>1 1 1 1</diffuse>
            <specular>1 1 1 1</specular>
            <pbr>
              <metal>
                <albedo_map>materials/textures/Counter_Albedo.png</albedo_map>
                <normal_map>materials/textures/Counter_Normal.png</normal_map>
                <roughness>0.2</roughness>
              </metal>
            </pbr>
          </material>
        </visual>
        <visual name='visual_silver'>
          <geometry>
            <mesh>
              <scale>1 1 1</scale>
              <uri>/root/.gazebo/models/Vanity/meshes/vanity.dae</uri>
              <submesh>
                <name>Silver</name>
                <center>0</center>
              </submesh>
            </mesh>
          </geometry>
          <material>
            <diffuse>1 1 1 1</diffuse>
            <specular>1 1 1 1</specular>
            <pbr>
              <metal>
                <metalness>1</metalness>
                <roughness>0.2</roughness>
              </metal>
            </pbr>
          </material>
        </visual>
        <collision name='Box001'>
          <pose>0 -0.010652 0.379152 0 -0 0</pose>
          <geometry>
            <box>
              <size>1.21718 0.575318 0.758303</size>
            </box>
          </geometry>
          <max_contacts>10</max_contacts>
          <surface>
            <contact>
              <ode/>
            </contact>
            <bounce/>
            <friction>
              <torsional>
                <ode/>
              </torsional>
              <ode/>
            </friction>
          </surface>
        </collision>
        <collision name='Box002'>
          <pose>-0.272681 -0.305972 0.585342 1.5708 -0 0</pose>
          <geometry>
            <box>
              <size>0.010254 0.107767 0.034918</size>
            </box>
          </geometry>
          <max_contacts>10</max_contacts>
          <surface>
            <contact>
              <ode/>
            </contact>
            <bounce/>
            <friction>
              <torsional>
                <ode/>
              </torsional>
              <ode/>
            </friction>
          </surface>
        </collision>
        <collision name='Box003'>
          <pose>-0.184261 -0.305972 0.585342 1.5708 -0 0</pose>
          <geometry>
            <box>
              <size>0.010254 0.107767 0.034918</size>
            </box>
          </geometry>
          <max_contacts>10</max_contacts>
          <surface>
            <contact>
              <ode/>
            </contact>
            <bounce/>
            <friction>
              <torsional>
                <ode/>
              </torsional>
              <ode/>
            </friction>
          </surface>
        </collision>
        <collision name='Box004'>
          <pose>0.369992 -0.305972 0.663856 -1.57079 1.57079 3.14159</pose>
          <geometry>
            <box>
              <size>0.010254 0.107767 0.034918</size>
            </box>
          </geometry>
          <max_contacts>10</max_contacts>
          <surface>
            <contact>
              <ode/>
            </contact>
            <bounce/>
            <friction>
              <torsional>
                <ode/>
              </torsional>
              <ode/>
            </friction>
          </surface>
        </collision>
        <collision name='Box005'>
          <pose>0.369992 -0.305972 0.458689 -1.57079 1.57079 3.14159</pose>
          <geometry>
            <box>
              <size>0.010254 0.107767 0.034918</size>
            </box>
          </geometry>
          <max_contacts>10</max_contacts>
          <surface>
            <contact>
              <ode/>
            </contact>
            <bounce/>
            <friction>
              <torsional>
                <ode/>
              </torsional>
              <ode/>
            </friction>
          </surface>
        </collision>
        <collision name='Box006'>
          <pose>0.369992 -0.305972 0.253608 -1.57079 1.57079 3.14159</pose>
          <geometry>
            <box>
              <size>0.010254 0.107767 0.034918</size>
            </box>
          </geometry>
          <max_contacts>10</max_contacts>
          <surface>
            <contact>
              <ode/>
            </contact>
            <bounce/>
            <friction>
              <torsional>
                <ode/>
              </torsional>
              <ode/>
            </friction>
          </surface>
        </collision>
        <collision name='Box007'>
          <pose>-0.139849 0.209554 0.765791 0 -0 0</pose>
          <geometry>
            <box>
              <size>0.125907 0.033199 0.113379</size>
            </box>
          </geometry>
          <max_contacts>10</max_contacts>
          <surface>
            <contact>
              <ode/>
            </contact>
            <bounce/>
            <friction>
              <torsional>
                <ode/>
              </torsional>
              <ode/>
            </friction>
          </surface>
        </collision>
        <collision name='Box008'>
          <pose>0.13985 0.209554 0.765791 0 -0 0</pose>
          <geometry>
            <box>
              <size>0.125907 0.033199 0.113379</size>
            </box>
          </geometry>
          <max_contacts>10</max_contacts>
          <surface>
            <contact>
              <ode/>
            </contact>
            <bounce/>
            <friction>
              <torsional>
                <ode/>
              </torsional>
              <ode/>
            </friction>
          </surface>
        </collision>
        <collision name='Box009'>
          <pose>0 0.147483 0.795837 0 -0 0</pose>
          <geometry>
            <box>
              <size>0.042808 0.163859 0.17347</size>
            </box>
          </geometry>
          <max_contacts>10</max_contacts>
          <surface>
            <contact>
              <ode/>
            </contact>
            <bounce/>
            <friction>
              <torsional>
                <ode/>
              </torsional>
              <ode/>
            </friction>
          </surface>
        </collision>
        <self_collide>0</self_collide>
        <enable_wind>0</enable_wind>
        <kinematic>0</kinematic>
      </link>
      <pose>-0.026233 0.739904 0.230121 0 -0 0</pose>
    </model>
    <model name='Oven'>
      <static>1</static>
      <link name='base_link'>
        <visual name='visual_oven'>
          <geometry>
            <mesh>
              <scale>1 1 1</scale>
              <uri>/root/.gazebo/models/Oven/meshes/oven.dae</uri>
              <submesh>
                <name>Oven</name>
                <center>0</center>
              </submesh>
            </mesh>
          </geometry>
          <material>
            <diffuse>1 1 1 1</diffuse>
            <specular>1 1 1 1</specular>
            <pbr>
              <metal>
                <albedo_map>materials/textures/Oven_Albedo.png</albedo_map>
                <normal_map>materials/textures/Oven_Normal.png</normal_map>
                <roughness_map>materials/textures/Oven_Roughness.png</roughness_map>
                <metalness_map>materials/textures/Oven_Metalness.png</metalness_map>
              </metal>
            </pbr>
          </material>
        </visual>
        <visual name='visual_glass'>
          <geometry>
            <mesh>
              <scale>1 1 1</scale>
              <uri>/root/.gazebo/models/Oven/meshes/oven.dae</uri>
              <submesh>
                <name>Glass</name>
                <center>0</center>
              </submesh>
            </mesh>
          </geometry>
          <material>
            <diffuse>1 1 1 1</diffuse>
            <specular>1 1 1 1</specular>
            <pbr>
              <metal>
                <albedo_map>materials/textures/Glass.png</albedo_map>
                <roughness>0.1</roughness>
              </metal>
            </pbr>
          </material>
        </visual>
        <collision name='Box001'>
          <pose>-0.000304 -2e-06 0.517103 0 -0 0</pose>
          <geometry>
            <box>
              <size>0.691523 0.96649 1.03421</size>
            </box>
          </geometry>
          <max_contacts>10</max_contacts>
          <surface>
            <contact>
              <ode/>
            </contact>
            <bounce/>
            <friction>
              <torsional>
                <ode/>
              </torsional>
              <ode/>
            </friction>
          </surface>
        </collision>
        <self_collide>0</self_collide>
        <enable_wind>0</enable_wind>
        <kinematic>0</kinematic>
      </link>
      <pose>-0.006011 -0.778291 0.001796 0 -0 1.56303</pose>
    </model>
  </world>
</sdf>
